This is a test message.
An exception occurred
Traceback (most recent call last):
  File "/Users/josephblazick/Documents/GPT-CodeApp/backend/test.py", line 51, in <module>
    1 / 0
    ~~^~~
ZeroDivisionError: division by zero
2023-12-12 09:47:22,079 - MyLogger - ERROR - An exception occurred
Traceback (most recent call last):
  File "/Users/josephblazick/Documents/GPT-CodeApp/backend/test.py", line 56, in <module>
    1 / 0
    ~~^~~
ZeroDivisionError: division by zero
2023-12-12 09:47:34,800 - MyLogger - ERROR - An exception occurred
Traceback (most recent call last):
  File "/Users/josephblazick/Documents/GPT-CodeApp/backend/test.py", line 56, in <module>
    1 / 0
    ~~^~~
ZeroDivisionError: division by zero
2023-12-12 09:47:40,634 - MyLogger - ERROR - An exception occurred
Traceback (most recent call last):
  File "/Users/josephblazick/Documents/GPT-CodeApp/backend/test.py", line 56, in <module>
    1 / 0
    ~~^~~
ZeroDivisionError: division by zero
2023-12-12 09:47:44,765 - MyLogger - ERROR - An exception occurred
Traceback (most recent call last):
  File "/Users/josephblazick/Documents/GPT-CodeApp/backend/test.py", line 56, in <module>
    1 / 0
    ~~^~~
ZeroDivisionError: division by zero
2023-12-12 09:47:45,622 - MyLogger - ERROR - An exception occurred
Traceback (most recent call last):
  File "/Users/josephblazick/Documents/GPT-CodeApp/backend/test.py", line 56, in <module>
    1 / 0
    ~~^~~
ZeroDivisionError: division by zero
2023-12-12 09:47:46,298 - MyLogger - ERROR - An exception occurred
Traceback (most recent call last):
  File "/Users/josephblazick/Documents/GPT-CodeApp/backend/test.py", line 56, in <module>
    1 / 0
    ~~^~~
ZeroDivisionError: division by zero
(asctime) - MyLogger - ERROR - An exception occurred
Traceback (most recent call last):
  File "/Users/josephblazick/Documents/GPT-CodeApp/backend/test.py", line 55, in <module>
    1 / 0
    ~~^~~
ZeroDivisionError: division by zero
1702403504.203807 - MyLogger - ERROR - An exception occurred
Traceback (most recent call last):
  File "/Users/josephblazick/Documents/GPT-CodeApp/backend/test.py", line 55, in <module>
    1 / 0
    ~~^~~
ZeroDivisionError: division by zero
1702403527.255923 - MyLogger - ERROR - An exception occurred
Traceback (most recent call last):
  File "/Users/josephblazick/Documents/GPT-CodeApp/backend/test.py", line 55, in <module>
    1 / 0
    ~~^~~
ZeroDivisionError: division by zero
2023-12-12 09:52:51,197 - MyLogger - ERROR - An exception occurred
Traceback (most recent call last):
  File "/Users/josephblazick/Documents/GPT-CodeApp/backend/test.py", line 55, in <module>
    1 / 0
    ~~^~~
ZeroDivisionError: division by zero
